Workbook
Name _PL03: [1]CIPA!#REF!
Name __PL03: #REF!
Name _PL01: #REF!
Name Serviço: #REF!
Name Desculpas: #REF!
Name TLV: #REF!
Name _PL04: #REF!
Name servico: #REF!
Name Desculpas: #REF!
Name __PL03: #REF!
Name serviços: #REF!
Name _PL02: #REF!
Name TLV: #REF!
Name __PL03: #REF!
Name __PL04: #REF!
Name _PL02: #REF!
Name serviços.: #REF!
Name TLV: 'TLV _Andrea'!$A$1:$J$6
Name __PL03: #REF!
Name serviços: #REF!
Name serviços: #REF!
Name serviços.: #REF!
Name _PL02: #REF!
Name __PL02: #REF!
Name Serviço: #REF!
Name TLV: #REF!
Name ___PL03: #REF!
Name DadosExternos_1: 'Lista de Empresa'!$A$1:$C$1052
Name siglas: #REF!
Name _PL01: #REF!
Name _PL02: #REF!
Name Serviço: #REF!
Name TLV: TLV!$C$2:$I$7
Name _PL04: #REF!
Name Desculpas: #REF!
Name _PL01: #REF!
Name servico: #REF!
Name siglas: 'TLV _Andrea'!$A$12:$F$16
Name _PL01: #REF!
Name siglas: #REF!
Name siglas: #REF!
Name servico: #REF!
Name _PL04: #REF!
Name TLV: TLV!$C$2:$I$7
Name _PL04: #REF!
Name serviços.: #REF!
Name __PL01: #REF!

Sheet Capa 
K6: Nº Relatório | L6: 0000-1/2026.0 | T6: 0000 - | U6: 1 / 2026.0
L7: (Nº DA AMOSTRA) | T7: =$T$6 -> 0000 - | U7: 2 / 2026.0
T8: =$T$6 -> 0000 - | U8: 3 / 2026.0
T9: =$T$6 -> 0000 - | U9: 4 / 2026.0
T10: =$T$6 -> 0000 - | U10: 5 / 2026.0
K11: Data de Assinatura (Entrega do Relatório): | M11: Exemplo: | T11: =$T$6 -> 0000 - | U11: 6 / 2026.0
M12: 01 de janeiro de 2026. | T12: =$T$6 -> 0000 - | U12: 7 / 2026.0
T13: =$T$6 -> 0000 - | U13: 8 / 2026.0
T14: =$T$6 -> 0000 - | U14: 9 / 2026.0
T15: =$T$6 -> 0000 - | U15: 10 / 2026.0
T16: =$T$6 -> 0000 - | U16: 11 / 2026.0
T17: =$T$6 -> 0000 - | U17: 12 / 2026.0
K18: Empresa: | L18: 11342 Sociedade Fogas Ltda - Manaus | T18: =$T$6 -> 0000 - | U18: 13 / 2026.0
K19: Endereço: | L19: =VLOOKUP($L$18,'Lista de Empresa'!A:C,3,FALSE) -> Rua Rio Quixito, 86 - Vila Buriti Manaus/Amazonas | T19: =$T$6 -> 0000 - | U19: 14 / 2026.0
K20: CNPJ: | L20: =IF(ISERROR(VLOOKUP(L18,'Lista de Empresa'!A:B,2,FALSE)),"", IF(OR(ISNUMBER(FIND(".",VLOOKUP(L18,'Lista de Empresa'!A:B,2,FALSE))), ISNUMBER(FIND("-",VLOOKUP(L18,'Lista de Empresa'!A:B,2,FALSE))), ISNUMBER(FIND("/",VLOOKUP(L18,'Lista de Empresa'!A:B,2,FALSE)))), VLOOKUP(L18,'Lista de Empresa'!A:B,2,FALSE), IF(LEN(VLOOKUP(L18,'Lista de Empresa'!A:B,2,FALSE))=11, TEXT(VLOOKUP(L18,'Lista de Empresa'!A:B,2,FALSE),"000\.000\.000\-00"), TEXT(VLOOKUP(L18,'Lista de Empresa'!A:B,2,FALSE),"00\.000\.000\/0000\-00") ) ) ) -> 04.563.672/0001-66 | T20: =$T$6 -> 0000 - | U20: 15 / 2026.0
T21: =$T$6 -> 0000 - | U21: 16 / 2026.0
T22: =$T$6 -> 0000 - | U22: 17 / 2026.0
T23: =$T$6 -> 0000 - | U23: 18 / 2026.0
T24: =$T$6 -> 0000 - | U24: 19 / 2026.0
T25: =$T$6 -> 0000 - | U25: 20 / 2026.0
C28: CNPJ:
K34: Data: | L34: Mês de 2026

Sheet Doc Base
A2: 1. Objetivo
A41: 2. Abreviaturas Utilizadas
A97: ANEXO - RELATÓRIOS ANALÍTICOS

Sheet Hidrocarbonetos Aromáticos
A1: Relatório de Ensaio Analítico N. | E1: {='Capa '!T6:U6} -> 0000 - | F1: 1 / 2026.0
A2: Folha 01 de 02
A3: Dados do Cliente
A4: Razão Social: | B4: ='Capa '!L18 -> 11342 Sociedade Fogas Ltda - Manaus
A5: Endereço: | B5: ='Capa '!L19 -> Rua Rio Quixito, 86 - Vila Buriti Manaus/Amazonas
A6: Serviço: | B6: Monitoramentos de Agentes Químicos no Ambiente de Trabalho
A7: Informações do Colaborador (a)
A8: Colaborador (a):
A9: Função: | E9: Matrícula:
A10: Local da Coleta: | E10: Setor:
A11: Informações Técnicas de Amostragem
A12: Data da Avaliação: | D12: Volume de Ar Amostrado: | F12: =#REF! -> #REF! | G12: L
A13: Jornada de Tabalho: 44 Horas/Semanais | D13: Resp. pela coleta:
A15: Resultados das Análises dos Agentes Químicos
A16: Agente Químico Código e-Social | B16: Valor Encontrado | C16: Unidade | D16: ACGIH | F16: NR 15 | G16: Bases de Efeitos Críticos
D17: TWA | E17: STEL
A18: Benzeno | B18: =VLOOKUP(A18,TLV!H:P,9,FALSE) -> < 0,011 | C18: =VLOOKUP(A18,TLV!B:D,3,FALSE) -> ppm | D18: =VLOOKUP(A18,TLV!B:G,4,FALSE) -> 0.02 | E18: =VLOOKUP(A18,TLV!B:G,5,FALSE) -> - | F18: =VLOOKUP(A18,TLV!B:G,6,FALSE) -> - | G18: =VLOOKUP(A18,TLV!$H:$I,2,FALSE) -> Síndrome mielodisplásica; Leucemia mieolóide aguda; Leucemia; Efeitos hematológicos; Dano cromossômico
A19: =VLOOKUP($A$18,TLV!H:L,4,FALSE) -> Método NIOSH 1501
A20: =VLOOKUP(A18,TLV!B:C,2,FALSE) -> Cód. e-Social: 01.03.001
A21: Tolueno | B21: =VLOOKUP(A21,TLV!H:P,9,FALSE) -> < 0,003 | C21: =VLOOKUP(A21,TLV!B:D,3,FALSE) -> ppm | D21: =VLOOKUP(A21,TLV!B:G,4,FALSE) -> 20 | E21: =VLOOKUP(A21,TLV!B:G,5,FALSE) -> - | F21: =VLOOKUP(A21,TLV!B:G,6,FALSE) -> 78 | G21: =VLOOKUP(A21,TLV!$H:$I,2,FALSE) -> Danos no sistema nervoso central; Danos auditivos; Comprometimento da visão; Dano reprodutivo feminino; Aborto
A22: =VLOOKUP($A$21,TLV!H:L,4,FALSE) -> Método NIOSH 1501
A23: =VLOOKUP(A21,TLV!B:C,2,FALSE) -> Cód. e-Social: 01.03.001
A24: Xileno | B24: =VLOOKUP(A24,TLV!H:P,9,FALSE) -> < 0,003 | C24: =VLOOKUP(A24,TLV!B:D,3,FALSE) -> ppm | D24: =VLOOKUP(A24,TLV!B:G,4,FALSE) -> 20 | E24: =VLOOKUP(A24,TLV!B:G,5,FALSE) -> - | F24: =VLOOKUP(A24,TLV!B:G,6,FALSE) -> 78 | G24: =VLOOKUP(A24,TLV!$H:$I,2,FALSE) -> Irritações no TRS; Irritações nos olhos; Efeitos hematológicos; Ototoxicidade - apenas para o para-xileno e misturas contendo para-xileno; Comprometimento do SNC
A25: =VLOOKUP($A$24,TLV!H:L,4,FALSE) -> Método NIOSH 1501
A26: =VLOOKUP(A24,TLV!B:C,2,FALSE) -> Cód. e-Social: 01.03.001
A27: Cumeno | B27: =VLOOKUP(A27,TLV!H:P,9,FALSE) -> < 0,007 | C27: =VLOOKUP(A27,TLV!B:D,3,FALSE) -> ppm | D27: =VLOOKUP(A27,TLV!B:G,4,FALSE) -> 5 | E27: =VLOOKUP(A27,TLV!B:G,5,FALSE) -> - | F27: =VLOOKUP(A27,TLV!B:G,6,FALSE) -> 39 | G27: =VLOOKUP(A27,TLV!$H:$I,2,FALSE) -> Adenoma TRS; efeito neurológico
A28: =VLOOKUP($A$27,TLV!H:L,4,FALSE) -> Método NIOSH 1501
A29: =VLOOKUP(A27,TLV!B:C,2,FALSE) -> Cód. e-Social: 01.03.001
A30: Estireno | B30: =VLOOKUP(A30,TLV!H:P,9,FALSE) -> < 0,004 | C30: =VLOOKUP(A30,TLV!B:D,3,FALSE) -> ppm | D30: =VLOOKUP(A30,TLV!B:G,4,FALSE) -> 10 | E30: =VLOOKUP(A30,TLV!B:G,5,FALSE) -> 20 | F30: =VLOOKUP(A30,TLV!B:G,6,FALSE) -> 78 | G30: =VLOOKUP(A30,TLV!$H:$I,2,FALSE) -> Comprometimento do SNC; Comprometimento do sistema auditivo; Irritações no TRS; Neuropatia periférica; Desordens visuais
A31: =VLOOKUP($A$27,TLV!H:L,4,FALSE) -> Método NIOSH 1501
A32: =VLOOKUP(A30,TLV!B:C,2,FALSE) -> Cód. e-Social: 01.03.002
A33: Etilbenzeno | B33: =VLOOKUP(A33,TLV!H:P,9,FALSE) -> < 0,001 | C33: =VLOOKUP(A33,TLV!B:D,3,FALSE) -> ppm | D33: =VLOOKUP(A33,TLV!B:G,4,FALSE) -> 20 | E33: =VLOOKUP(A33,TLV!B:G,5,FALSE) -> - | F33: =VLOOKUP(A33,TLV!B:G,6,FALSE) -> 78 | G33: =VLOOKUP(A33,TLV!$H:$I,2,FALSE) -> Irritações no TRS; Irritações nos olhos; Danos nos rins (nefrotoxicidade); Comprometimento do SNC; Ototoxicidade
A34: =VLOOKUP($A$27,TLV!H:L,4,FALSE) -> Método NIOSH 1501
A35: =VLOOKUP(A33,TLV!B:C,2,FALSE) -> Cód. e-Social: 01.19.035
A36: Viniltolueno | B36: =VLOOKUP(A36,TLV!H:P,9,FALSE) -> < 0,003 | C36: =VLOOKUP(A36,TLV!B:D,3,FALSE) -> ppm | D36: =VLOOKUP(A36,TLV!B:G,4,FALSE) -> 10 | E36: =VLOOKUP(A36,TLV!B:G,5,FALSE) -> - | F36: =VLOOKUP(A36,TLV!B:G,6,FALSE) -> - | G36: =VLOOKUP(A36,TLV!$H:$I,2,FALSE) -> Danos TRS e pulmão
A37: =VLOOKUP($A$27,TLV!H:L,4,FALSE) -> Método NIOSH 1501
A38: =VLOOKUP(A36,TLV!B:C,2,FALSE) -> Cód. e-Social: N. C.
A39: α Metil Estireno | B39: =VLOOKUP(A39,TLV!H:P,9,FALSE) -> < 0,003 | C39: =VLOOKUP(A39,TLV!B:D,3,FALSE) -> ppm | D39: =VLOOKUP(A39,TLV!B:G,4,FALSE) -> 10 | E39: =VLOOKUP(A39,TLV!B:G,5,FALSE) -> - | F39: =VLOOKUP(A39,TLV!B:G,6,FALSE) -> - | G39: =VLOOKUP(A39,TLV!$H:$I,2,FALSE) -> Irritações no TRS; Danos nos rins; Dano reprodutivo feminino
A40: =VLOOKUP($A$27,TLV!H:L,4,FALSE) -> Método NIOSH 1501
A41: =VLOOKUP(A39,TLV!B:C,2,FALSE) -> Cód. e-Social: 01.03.001
...

Sheet Var. Metais
A1: Relatório de Ensaio Analítico N. | E1: {='Capa '!T6:U6} -> 0000 - | F1: 1 / 2026.0
A2: Folha 01 de 03
A3: Dados do Cliente
A4: Razão Social: | B4: ='Capa '!L18 -> 11342 Sociedade Fogas Ltda - Manaus
A5: Endereço: | B5: ='Capa '!L19 -> Rua Rio Quixito, 86 - Vila Buriti Manaus/Amazonas
A6: Serviço: | B6: Monitoramento de Agentes Químicos no Ambiente de Trabalho | I6: Hora Final | J6: 0.5
A7: Informações do Colaborador (a) | I7: Hora Inicial | J7: 0.33333333
A8: Colaborador (a): | J8: =J6-J7 -> 0.16666667
A9: Função: | E9: Matrícula: | J9: =HOUR(J8)*60+MINUTE(J8) -> 240 | K9: min
A10: Local da Coleta: | E10: Setor: | I10: Vazão: | J10: 0.02 | K10: min/L
A11: Informações Técnicas de Amostragem | I11: Volume: | J11: =J10*J9 -> 4.8 | K11: L
A12: Data da Avaliação: | B12: 45471 | D12: Volume de Ar Amostrado: | F12: =$J$11 -> 4.8 | G12: L
A13: Jornada de Tabalho: 44 Horas/Semanais | D13: Resp. pela coleta: | F13: Willian Douglas Brito
A15: Resultado da Análise do Agente Químico
A16: Agente Químico Código e-Social | B16: Valor | C16: Unidade | D16: ACGIH | F16: NR 15 | G16: Bases de Efeitos Críticos
B17: Encontrado | D17: TWA | E17: STEL
A18: Alumínio | B18: =VLOOKUP(A18,TLV!H:P,9,FALSE) -> < 0,005 | C18: =VLOOKUP(A18,TLV!B:D,3,FALSE) -> mg/m3 | D18: =VLOOKUP(A18,TLV!B:G,4,FALSE) -> 1 | E18: =VLOOKUP(A18,TLV!B:G,5,FALSE) -> - | F18: =VLOOKUP(A18,TLV!B:G,6,FALSE) -> - | G18: =VLOOKUP(A18,TLV!$H:$I,2,FALSE) -> Pneumoconiose; Irritação TRI neurotoxicidade
A19: =VLOOKUP(A18,TLV!H:L,4,FALSE) -> Método NIOSH 7303
A20: =VLOOKUP(A18,TLV!B:C,2,FALSE) -> Cód. e-Social: N. C.
A21: Antimônio | B21: =VLOOKUP(A21,TLV!H:P,9,FALSE) -> < 0,005 | C21: =VLOOKUP(A21,TLV!B:D,3,FALSE) -> mg/m3 | D21: =VLOOKUP(A21,TLV!B:G,4,FALSE) -> 0.5 | E21: =VLOOKUP(A21,TLV!B:G,5,FALSE) -> - | F21: =VLOOKUP(A21,TLV!B:G,6,FALSE) -> - | G21: =VLOOKUP(A21,TLV!$H:$I,2,FALSE) -> Irritações na pele; Irritações no TRS
A22: =VLOOKUP(A21,TLV!H:L,4,FALSE) -> Método NIOSH 7303
A23: =VLOOKUP(A21,TLV!B:C,2,FALSE) -> Cód. e-Social: N. C.
A24: Arsênio | B24: =VLOOKUP(A24,TLV!H:P,9,FALSE) -> < 0,005 | C24: =VLOOKUP(A24,TLV!B:D,3,FALSE) -> mg/m3 | D24: =VLOOKUP(A24,TLV!B:G,4,FALSE) -> 0.01 | E24: =VLOOKUP(A24,TLV!B:G,5,FALSE) -> - | F24: =VLOOKUP(A24,TLV!B:G,6,FALSE) -> - | G24: =VLOOKUP(A24,TLV!$H:$I,2,FALSE) -> Câncer do pulmão
A25: =VLOOKUP(A24,TLV!H:L,4,FALSE) -> Método NIOSH 7303
A26: =VLOOKUP(A24,TLV!B:C,2,FALSE) -> Cód. e-Social: 01.01.001
A27: Bário | B27: =VLOOKUP(A27,TLV!H:P,9,FALSE) -> < 0,001 | C27: =VLOOKUP(A27,TLV!B:D,3,FALSE) -> mg/m3 | D27: =VLOOKUP(A27,TLV!B:G,4,FALSE) -> 0.5 | E27: =VLOOKUP(A27,TLV!B:G,5,FALSE) -> - | F27: =VLOOKUP(A27,TLV!B:G,6,FALSE) -> - | G27: =VLOOKUP(A27,TLV!$H:$I,2,FALSE) -> Irritação olhos, pele e GI; estim muscular
A28: =VLOOKUP(A27,TLV!H:L,4,FALSE) -> Método NIOSH 7303
A29: =VLOOKUP(A27,TLV!B:C,2,FALSE) -> Cód. e-Social: N. C.
A30: Cádmio | B30: =VLOOKUP(A30,TLV!H:P,9,FALSE) -> < 0,001 | C30: =VLOOKUP(A30,TLV!B:D,3,FALSE) -> mg/m3 | D30: =VLOOKUP(A30,TLV!B:G,4,FALSE) -> 0.002 | E30: =VLOOKUP(A30,TLV!B:G,5,FALSE) -> - | F30: =VLOOKUP(A30,TLV!B:G,6,FALSE) -> - | G30: =VLOOKUP(A30,TLV!$H:$I,2,FALSE) -> Dano rins
A31: =VLOOKUP(A30,TLV!H:L,4,FALSE) -> Método NIOSH 7303
A32: =VLOOKUP(A30,TLV!B:C,2,FALSE) -> Cód. e-Social: 01.06.001
A33: Chumbo | B33: =VLOOKUP(A33,TLV!H:P,9,FALSE) -> < 0,001 | C33: =VLOOKUP(A33,TLV!B:D,3,FALSE) -> mg/m3 | D33: =VLOOKUP(A33,TLV!B:G,4,FALSE) -> 0.05 | E33: =VLOOKUP(A33,TLV!B:G,5,FALSE) -> - | F33: =VLOOKUP(A33,TLV!B:G,6,FALSE) -> 0.1 | G33: =VLOOKUP(A33,TLV!$H:$I,2,FALSE) -> Comprometimento do SNC; Comprometimento do sistema nervoso periférico; Efeitos hematológicos
A34: =VLOOKUP(A33,TLV!H:L,4,FALSE) -> Método NIOSH 7303
A35: =VLOOKUP(A33,TLV!B:C,2,FALSE) -> Cód. e-Social: 01.08.001
A36: Cobalto | B36: =VLOOKUP(A36,TLV!H:P,9,FALSE) -> < 0,005 | C36: =VLOOKUP(A36,TLV!B:D,3,FALSE) -> mg/m3 | D36: =VLOOKUP(A36,TLV!B:G,4,FALSE) -> 0.02 | E36: =VLOOKUP(A36,TLV!B:G,5,FALSE) -> - | F36: =VLOOKUP(A36,TLV!B:G,6,FALSE) -> - | G36: =VLOOKUP(A36,TLV!$H:$I,2,FALSE) -> Mudanças na função pulmonar.
A37: =VLOOKUP(A36,TLV!H:L,4,FALSE) -> Método NIOSH 7303
A38: =VLOOKUP(A36,TLV!B:C,2,FALSE) -> Cód. e-Social: N. C.
A39: Cobre | B39: =VLOOKUP(A39,TLV!H:P,9,FALSE) -> < 0,005 | C39: =VLOOKUP(A39,TLV!B:D,3,FALSE) -> mg/m3 | D39: =VLOOKUP(A39,TLV!B:G,4,FALSE) -> 1 | E39: =VLOOKUP(A39,TLV!B:G,5,FALSE) -> - | F39: =VLOOKUP(A39,TLV!B:G,6,FALSE) -> - | G39: =VLOOKUP(A39,TLV!$H:$I,2,FALSE) -> Irritação; GI; febre dos fumos metálicos
A40: =VLOOKUP(A39,TLV!H:L,4,FALSE) -> Método NIOSH 7303
A41: =VLOOKUP(A39,TLV!B:C,2,FALSE) -> Cód. e-Social: N. C.
...

Sheet Anexos
A25: ANEXO B - DOCUMENTOS E CERTIFICADOS DE CALIBRAÇÃO

Sheet TLV
B1: 1 | C1: 2 | D1: 3 | E1: 4 | F1: 5 | G1: 6 | H1: 1 | I1: 2 | J1: 3 | K1: 4 | L1: 5 | M1: 6 | N1: 7 | O1: 8 | P1: 9 | Q1: 10
A2: Grupos | B2: Agente | C2: e-Social | D2: Unidade | E2: TWA | F2: STEL | G2: NR 15 | H2: Agente | I2: Bases de Efeitos Críticos | J2: Amostrador/Filtro | K2: Método | L2: Método de Análise | M2: Vazão | N2: Volume | O2: L.Q | P2: Valor Encontrado | Q2: CAS
A3: VOC | B3: 1,1,2,2 Tetracloroetano | C3: Cód. e-Social: N. C. | D3: ppm | E3: 1 | F3: - | G3: 4 | H3: 1,1,2,2 Tetracloroetano | I3: Dano fígado | K3: Método NIOSH 2562 | L3: Cromatografia | M3: 0,02 - 0,2 | N3: 3 - 30 | Q3: 106-99-0
A4: VOC | B4: 1,3-Butadieno | C4: Cód. e-Social:01.19.003 | D4: ppm | E4: 2 | F4: - | G4: 780 | H4: 1,3-Butadieno | I4: Câncer | J4: Tubo de Carvão Ativado | K4: Método NIOSH 1024 | L4: Cromatografia | M4: 0,02 - 0,5 | N4: 5 - 25 | O4: < 0,004 | P4: < 0,004 | Q4: 111-76-2
A5: VOC | B5: 1-Methoxy-2-propanol | C5: Cód. e-Social: N. C. | D5: ppm | E5: 50 | F5: 100 | G5: - | H5: 1-Methoxy-2-propanol | I5: Irritações nos olhos; Irritações no TRS | J5: Tubo de Carvão Ativado | K5: OSHA 99 | L5: Cromatografia | M5: 0,1 - 0,2 | N5: 3 - 25 | O5: 2 | P5: 2 | Q5: 708-85-0
A6: VOC | B6: 2-Butoxietanol | C6: Cód. e-Social: N. C. | D6: ppm | E6: 20 | F6: - | G6: 39 | H6: 2-Butoxietanol | I6: Irritação olhos e TRS | J6: Tubo de Carvão Ativado | K6: Método NIOSH 1403 | L6: Cromatografia | M6: 0,02 - 0,2 | N6: 1 - 10 | O6: < 0,009 | P6: < 0,009 | Q6: 110-8-5
A7: VOC | B7: 2-Cianoacrilato de etila | C7: Cód. e-Social: N. C. | D7: ppm | E7: 0.2 | F7: 1 | G7: - | H7: 2-Cianoacrilato de etila | I7: Irritações nos olhos; Irritações TRS; Asma | J7: Tubo de Carvão Ativado | K7: Método OSHA 55 - HPLC | L7: Cromatografia | M7: 0,02 - 0,2 | N7: 1,5 - 12 | O7: <0,0005 | P7: < 0,0005 | Q7: 75-07-0
A8: ABC | B8: 2-Etoxietanol | C8: Cód. e-Social: N. C. | D8: ppm | E8: 5 | F8: - | G8: 78 | H8: 2-Etoxietanol | I8: Dano embrio/fetal; Dano reprodutivo masculino | J8: Tubo de Carvão Ativado | K8: Método NIOSH 1403 | L8: Cromatografia | M8: 0,02 - 0,05 | N8: 6 | O8: <0,007 | P8: < 0,007 | Q8: 112-07-2
A9: ABC | B9: 2-propanol | C9: Cód. e-Social: N. C. | D9: ppm | E9: 200 | F9: 400 | G9: 310 | H9: 2-propanol | I9: Irritações nos olhos; Irritações no trato respiratório superior; Comprometimento do sistema nervoso central | J9: Tubo de Carvão Ativado | K9: Método NIOSH 1400 | L9: Cromatografia | M9: 0,02 - 0,2 | N9: 0,2 - 3 | Q9: 111-15-9
A10: ABC | B10: Acetaldeído | C10: Cód. e-Social: N. C. | D10: ppm | E10: - | F10: 25 | G10: 78 | H10: Acetaldeído | I10: Irritações no trato respiratório superior; Irritações nos olhos | J10: Tubo de Sílica gel | K10: Método EPA 8315 | L10: Cromatografia | M10: 0,1 - 1,5 | N10: 15 | O10: < 0,001 | P10: < 0,001 | Q10: 111-15-9
A11: ABC | B11: Acetato de 2-Butóxietanol | C11: Cód. e-Social: N. C. | D11: ppm | E11: 20 | F11: - | G11: - | H11: Acetato de 2-Butóxietanol | I11: Hemólise | J11: Tubo de Carvão Ativado | K11: Método OSHA 83 | L11: Cromatografia | M11: 1 | N11: 48 | Q11: 141-78-6
B12: Acetato de 2-etoxietanol | C12: Cód. e-Social: N. C. | D12: ppm | E12: 5 | F12: - | G12: 78 | H12: Acetato de 2-etoxietanol | I12: Dano reprodutivo masculino | J12: Tubo de Carvão Ativado | K12: Método NIOSH 1450 | L12: Cromatografia | M12: 0,02 - 0,2 | N12: 1 - 10 | O12: <0,010 | P12: < 0,010 | Q12: 105-46-4
B13: Acetato de 2-etoxietila | C13: Cód. e-Social: N. C. | D13: ppm | E13: 5 | F13: - | G13: 78 | H13: Acetato de 2-etoxietila | I13: Dano reprodutivo masculino. | J13: Tubo de Carvão Ativado | K13: Método NIOSH 1450 | L13: Cromatografia | M13: 0,02 - 0,2 | N13: 1 - 10 | O13: < 0,002 | P13: < 0,002 | Q13: 108-21-4
B14: Acetato de 2-Metoxietila | C14: Cód. e-Social: N. C. | D14: ppm | E14: 0.1 | F14: - | G14: - | H14: Acetato de 2-Metoxietila | I14: Efe Hematológico e reprodutivo | J14: Tubo de Carvão Ativado | K14: Método NIOSH 1451 | L14: Cromatografia | M14: 0,02 - 0,2 | N14: 0,2 - 20 | Q14: 79-20-9
B15: Acetato de Butila | C15: Cód. e-Social: N. C. | D15: ppm | E15: 50 | F15: 150 | G15: - | H15: Acetato de Butila | I15: Irritação nos olhos e no TRS. | J15: Tubo de Carvão Ativado | K15: Método NIOSH 1450 | L15: Cromatografia | M15: 0,02 - 0,2 | N15: 1 - 10 | O15: < 0,010 | P15: < 0,010 | Q15: 110-49-6
B16: Acetato de etila | C16: Cód. e-Social: N. C. | D16: ppm | E16: 400 | F16: - | G16: 310 | H16: Acetato de etila | I16: Irritações no trato respiratório superior; Irritações nos olhos | J16: Tubo de Carvão Ativado | K16: Método NIOSH 1457 | L16: Cromatografia | M16: 0,02 - 0,2 | N16: 1 - 10 | O16: < 0,007 | P16: < 0,007 | Q16: 105-46-4
B17: Acetato de isobutila | C17: Cód. e-Social: N. C. | D17: ppm | E17: 50 | F17: 150 | G17: - | H17: Acetato de isobutila | I17: Irritação nos olhos e no TRS. | J17: Tubo de Carvão Ativado | K17: Método NIOSH 1450 | L17: Cromatografia | M17: 0,01 - 0,2 | N17: 1 - 10 | O17: < 0,002 | P17: < 0,002 | Q17: 123-86-4 | R17: Tempo: 360
B18: Acetato de isopropila | C18: Cód. e-Social: N. C. | D18: ppm | E18: 100 | F18: 150 | G18: - | H18: Acetato de isopropila | I18: Irritação nos olhos e pele. | J18: Tubo de Carvão Ativado | K18: Método NIOSH 1454 | L18: Cromatografia | M18: 0,02 - 0,2 | N18: 0,1 - 9 | O18: < 0,008 | P18: < 0,008 | Q18: 108-21-4
B19: Acetato de metila | C19: Cód. e-Social: N. C. | D19: ppm | E19: 200 | F19: 250 | G19: - | H19: Acetato de metila | I19: Dor de cabeça; Tontura; Náusea; Dano olhos (degeneração das células ganglionares da retina). | J19: Tubo de Carvão Ativado | K19: Método NIOSH 1458 | L19: Cromatografia | M19: 0,02 - 0,2 | N19: 0,2 - 10 | O19: < 0,007 | P19: < 0,007 | Q19: 107-98-2
B20: Acetato de n-butila | C20: Cód. e-Social: N. C. | D20: ppm | E20: 50 | F20: 150 | G20: - | H20: Acetato de n-butila | I20: Irritação nos olhos e no TRS. | J20: Tubo de Carvão Ativado | K20: Método NIOSH 1450 | L20: Cromatografia | M20: 0,02 - 0,2 | N20: 1 - 10 | Q20: 61-64-1
B21: Acetato de N-Propila | C21: Cód. e-Social: N. C. | D21: ppm | E21: 100 | F21: 150 | G21: - | H21: Acetato de N-Propila | I21: Irritações TRS; Irritações nos olhos; Comprometimento do SNC | J21: Tubo de Carvão Ativado | K21: Método NIOSH 1450 | L21: Cromatografia | M21: 0,01 - 0,2 | N21: 1 - 10 | Q21: 64-19-7
B22: Acetato de Vinila | C22: Cód. e-Social: N. C. | D22: ppm | E22: 10 | F22: 15 | G22: - | H22: Acetato de Vinila | I22: Irritação no TRS. | J22: Tubo de Carvão Ativado | K22: Método NIOSH 1453 | L22: Cromatografia | M22: 0,05 - 0,2 | N22: 1,5 - 24 | Q22: 7647-01-0
B23: Acetona | C23: Cód. e-Social: N. C. | D23: ppm | E23: 250 | F23: 500 | G23: 780 | H23: Acetona | I23: Comprometimento do SNC; Irritações noTRS; Irritações nos olhos | J23: Tubo de Carvão Ativado | K23: Método NIOSH 1300 | L23: Cromatografia | M23: 0,02 - 0,2 | N23: 0,5 - 3 | O23: < 0,008 | P23: < 0,008 | Q23: 7664-39-3
B24: Acetonitrila | C24: Cód. e-Social: N. C. | D24: ppm | E24: 20 | F24: - | G24: 30 | H24: Acetonitrila | I24: Irritação no TRI | J24: Tubo de Carvão Ativado | K24: Método NIOSH 1606 | L24: Cromatografia | M24: 0,02 - 0,2 | N24: 3 - 25 | Q24: 64-18-6
B25: Ácido acético | C25: Cód. e-Social: N. C. | D25: ppm | E25: 10 | F25: 15 | G25: 8 | H25: Ácido acético | I25: Comprometimento da função pulmonar; Irritações no trato respiratório superior; Irritações nos olhos | J25: Tubo de Carvão Ativado | K25: Método NIOSH 1603 | L25: Cromatografia | M25: 0,02 - 1 | N25: 20 - 300 | O25: < 0,002 | P25: < 0,002 | Q25: 7664-38-2
B26: Ácido Bórico - como Borato, compostos inogânicos | C26: Cód. e-Social: N. C. | D26: mg/m3 | E26: 2 | F26: 6 | G26: - | H26: Ácido Bórico - como Borato, compostos inogânicos | I26: Irritação TRS | J26: Filtro de éster de celulose | K26: Método NIOSH 7303 | L26: Espectrofotometria | M26: 1 - 4 | N26: 240 - 960 | Q26: 7697-37-2
B27: Ácido Carboxílico de Hidrogênio | C27: Cód. e-Social: N. C. | D27: ppm | E27: 5 | F27: - | G27: 4 | H27: Ácido Carboxílico de Hidrogênio | I27: Irritações no trato respiratório superior | J27: Tubo de Carvão Ativado | K27: Método NIOSH 2011 | L27: Cromatografia | M27: 0,05 - 0,2 | N27: 1 - 24 | Q27: 79-21-0
B28: Ácido clorídrico | C28: Cód. e-Social: 01.09.001 | D28: ppm | E28: - | F28: 2 | G28: 4 | H28: Ácido clorídrico | I28: Irritações no TRS | J28: Tubo de Sílica gel | K28: Método OSHA ID165-SG / OSHA ID-174-SG | L28: Cromatografia | M28: 2 | N28: 30 - 600 | O28: < 0,005 | P28: < 0,005 | Q28: 7664-93-9
B29: Ácido fluorídrico | C29: Cód. e-Social: N. C. | D29: ppm | E29: 0.5 | F29: 2 | G29: 2,5 | H29: Ácido fluorídrico | I29: Irritações no TRS; Irritações noTRI; Irritações na pele; Irritações nos olhos; Fluorese. | J29: Filtro de éster de celulose | K29: Método NIOSH 7902 | L29: Cromatografia | M29: 1 - 2 | N29: 15 - 1000 | O29: < 0,002 | P29: < 0,002 | Q29: 64-17-5
B30: Ácido fórmico | C30: Cód. e-Social: N. C. | D30: ppm | E30: 5 | F30: - | G30: 4 | H30: Ácido fórmico | I30: Irritações no TRS | J30: Tubo de Sílica gel | K30: Método NIOSH 2011 | L30: Cromatografia | M30: 0,05 - 0,2 | N30: 1 - 24 | O30: < 0,002 | P30: < 0,002 | Q30: 67-63-0
B31: Ácido fosfórico | C31: Cód. e-Social: 01.12.001 | D31: mg/m3 | E31: 1 | F31: 3 | G31: - | H31: Ácido fosfórico | I31: Irritações nos olhos; Irritações na pele; Irritações no trato respiratório superior | J31: Tubo de Sílica gel | K31: Método OSHA ID165-SG / OSHA ID-174-SG | L31: Cromatografia | M31: 1 - 5 | N31: 15 - 2000 | O31: < 0,005 | P31: < 0,005 | Q31: 107-13-1
B32: Ácido nítrico | C32: Cód. e-Social: N. C. | D32: ppm | E32: 2 | F32: 4 | G32: - | H32: Ácido nítrico | I32: Irritação olhos e TRS; corrosão dental | J32: Tubo de Sílica gel | K32: Método OSHA ID165-SG / OSHA ID-174-SG | L32: Cromatografia | M32: 2 | N32: 30 - 600 | O32: < 0,005 | P32: < 0,005 | Q32: 96-33-3
B33: Ácido peracético | C33: Cód. e-Social: N. C. | D33: ppm | E33: - | F33: 0.4 | G33: - | H33: Ácido peracético | I33: Irritação olhos, pele e TRS | J33: Tubo de Sílica gel | K33: Método IT 10-220 | L33: Cromatografia | M33: 1 | N33: 15 - 120 | O33: < 0,005 | P33: < 0,005 | Q33: 71-36-3
B34: Ácido Sulfúrico | C34: Cód. e-Social: N. C. | D34: mg/m3 | E34: 0.2 | F34: - | G34: - | H34: Ácido Sulfúrico | I34: Função pulmonar | J34: Filtro de éster de celulose | K34: Método OSHA ID-113 | L34: Cromatografia | M34: 1.6 | N34: 480 | O34: < 0,001 | P34: < 0,001 | Q34: 7429-90-5
B35: Acrilato de Etila | C35: Cód. e-Social: N. C. | D35: ppm | E35: 5 | F35: 15 | G35: - | H35: Acrilato de Etila | I35: Irritações gastrointestinal; Irritações no trato respiratório superior; Irritações nos olhos; Comprometimento do sistema nervoso central; Sensibilidade na pele | J35: Tubo de Carvão Ativado | K35: Método NIOSH 1450 | L35: Cromatografia | M35: 0,02 - 0,2 | N35: 1-10 | Q35: 12172-73-5
B36: Acrilato de Metila | D36: ppm | E36: 2 | G36: 8 | H36: Acrilato de Metila | I36: Irritações nos olhos; Irritações na pele; Irritações no trato respiratório superior; Danos nos olhos | J36: Tubo de Carvão Ativado | K36: Método NIOSH 1459 | L36: Espectrofotometria | M36: 0,02 - 0,2 | N36: 1 - 5 | O36: <0,004 | P36: < 0,004 | Q36: 7664-41-7
B37: Acrilonitrila | C37: Cód. e-Social: 01.19.002 | D37: ppm | E37: 2 | F37: - | G37: 16 | H37: Acrilonitrila | I37: Comprometimento do SNC; Irritações no TRI | J37: Tubo de Carvão Ativado | K37: Método NIOSH 1604 | L37: Espectrofotometria | M37: 0,02 - 0,2 | N37: 3,5 - 20 | O37: <0,002 | P37: < 0,002 | Q37: 7440-36-0
B38: Álcool Etílico | C38: Cód. e-Social: N. C. | D38: ppm | E38: - | F38: 1000 | G38: 780 | H38: Álcool Etílico | I38: Irritação TRS | J38: Tubo de Carvão Ativado | K38: Método NIOSH 1400 | L38: Cromatografia | M38: 0,02 - 0,05 | N38: 0,1 - 1 | O38: < 0,007 | P38: < 0,007 | Q38: 7440-38-2
B39: Álcool Isopropílico | C39: Cód. e-Social: N. C. | D39: ppm | E39: 200 | F39: 400 | G39: 310 | H39: Álcool Isopropílico | I39: Irritações nos olhos; Irritações noTRS; Comprometimento do SNC | J39: Tubo de Carvão Ativado | K39: Método NIOSH 1400 | L39: Cromatografia | M39: 0,02 - 0,2 | N39: 0,2 - 3 | O39: < 0,007 | P39: < 0,007 | Q39: 7440-39-3
B40: Álcool Metílico | C40: Cód. e-Social: N. C. | D40: ppm | E40: 200 | F40: 250 | G40: 156 | H40: Álcool Metílico | I40: Dor de Cabeça; Danos nos olhos; Tontura; Nausea | J40: Tubo de Carvão Ativado | K40: Método NIOSH 1400 | L40: Cromatografia | M40: 0,02 - 0,2 | N40: 1-5 | Q40: 71-43-2
...

Sheet Lista de Empresa
A1: Identificação | B1: CNPJ | C1: Endereçoo
A2: Labsoft | B2: 05.412.271/0001-78 | C2: Rua Vigário João José Rodrigues, 905 - 7º Andar Centro Jundiaí/São Paulo
A3: 11342 Sociedade Fogas Ltda - Manaus | B3: 4563672000166 | C3: Rua Rio Quixito, 86 - Vila Buriti Manaus/Amazonas
A4: Sociedade Fogas Ltda - Santarém | B4: 04563672000590 | C4: Avenida Cuiba, Lote 5 - Area Portuária da CIA, doca do Pará Sale Santarém/Pará
A5: Placibras da Amazônia Ltda | B5: 5338882000202 | C5: Avenida Autaz Mirim, 2645 - Armando Mendes Manaus/Amazonas
A6: Componel Industria e Comércio Ltda | B6: 57593253000567 | C6: Avenida Açaí, 1325 - Distrito Industrial Manaus/Amazonas
A7: Pam Industria de Plasticos Injetados Ltda - Filial (04.413.977/0007-87) | B7: 4413977000787 | C7: Avenida Solimões, 105 - Lote 2.31 Distrito Industrial I Manaus/Amazonas
A8: Stratura Asfaltos S.A | B8: 59128553001220 | C8: Av. Rodrigo Otávio, 2.890 - Sala 03 Centro Comercial Distrito Industrial I Manaus/Amazonas
A9: Naturex - Ingredientes Naturais Ltda | B9: 3899381000180 | C9: Av. Buriti, 5.391 - Distrito Industrial Manaus/Amazonas
A10: 11349 Hisamitsu Farmaceutica do Brasil Ltda | B10: 49383250000147 | C10: Av. Buriti, 1.050 - Distrito Industrial Manaus/Amazonas
A11: Andrade Gutierrez Engenharia S/A | B11: 17262213025936 | C11: Av. Djalma Batista, 3.637 - Sala 08 Flores Manaus/Amazonas
A12: Tigre Materiais e Soluções Para Construção Ltda. | B12: 8862530000584 | C12: Av. Buriti, 3.501 - Lote 03 Distrito Industrial I Manaus/Amazonas
... A25: 11364 Flex Impor. Expor. Ind. E Comércio de Máquina e Motores Ltda | B25: 22798094000129 | C25: Av. Buriti, 4.821 - Distrito Industrial Manaus/Amazonas
A26: 11365 Flex Impor. Expor. Ind. E Comércio de Máquina e Motores Ltda (Galpão 01) | C26: Rua da Granja Azul, 03 - Galpão 01 Colônia Oliveira Machado Manaus/Amazonas
A27: Amazon Industria de Gelo e Bebidas Ltda | B27: 02402867000522 | C27: Rua da Granja Azul, n° 03 - Galpão 01 Col. Oliveira Machado Manaus/Amazonas
A28: J Cruz Indústria de Bebidas Ltda (Amazon Refrigerante - Filial) | B28: 4398251000550 | C28: Rua José Romão, 452 - São José Operário Manaus/Amazonas
A29: 11368 D.D Williamson do Brasil Ltda | B29: 02789565000125 | C29: Av. Buriti, 5.680 - Distrito Industral Manaus/Amazonas
A30: 11369 Eternal Ind. Com. Serv. e Trat de Resíduos da Amazônia Ltda | B30: 84527274000123 | C30: Rua Guiana Francesa, 01 - Distrito Industial II Manaus/Amazonas
A31: GRI Koleta - Gerenciamento de Resíduos Industriais S.A | B31: 4517241001135 | C31: Rua Constelação de Gêmeos, 169 - Galpão 02 Aleixo Manaus/Amazonas
A32: F E Isaías de Lima (Ceramica LIMA) | B32: 22815369000195 | C32: Rural S/N - Km 40 - Rural S/N - Km 40 - Área Rural de Manacapuru Manacapuru Manaus/Amazonas
A33: Sodecia Automotive Manaus Ltda | B33: 2499629000153 | C33: Rua Gisele, 1.000 - Mauazinho Manaus/Amazonas
A34: Amcor Embalagens da Amazônia Ltda | B34: 84127208000166 | C34: Rua Anhandui, 306 - Edifício D Flores Manaus/Amazonas
A35: Musashi da Amazônia Ltda | B35: 4944068000180 | C35: Av. Flamboyant, 931 - Distrito Industrial II Manaus/Amazonas
A36: 11375 Caloi Norte S.A | B36: 4301024000131 | C36: Av. Abiurana, 150 A - Distrito Industrial Manaus/Amazonas
A37: 11376 Agropecuária Jayoro Ltda | B37: 5827977000109 | C37: Est. BR 174 S/N - Zona Rural Ramal 14 Km 120 Presidente Figueiredo/Amazonas
A38: Norte Ambiental Tratamento de Resíduos Ltda | B38: 14214776000119 | C38: Est. Manoel Urbano S/N - Km 02 Iranduba/Amazonas
... A411: VP FLEXGEN BRAZIL SPE LTDA - HUMAITA | B411: 28231767000574 | C411: Rua 01 S/N° - Parque Industrial Humaitá/Amazonas
A412: TST José Emiliano da Silva | B412: 00063597330215
A413: BDA Serviços em construção e Comercio EIRELI | B413: 17010074000101 | C413: Av. Jutai, n° 124 - Nossa Senhora das Graças Manaus/Amazonas
A414: Procter e Gamble do Brasil S.A - Rio Solimões | B414: 59476770000158 | C414: Av. Guaruba, Nº 740 Distrito Industrial Manaus/Amazonas
A415: Francilene Mendonça da Silva (Marajoara) | B415: 31785469000107 | C415: Rua Marrocos, nº 190 - Flores Manaus/Amazonas
A416: Jr Comércio de Artefatos Metálicos Ltda | B416: 09565801000179 | C416: São Tomaz de Aquino, nº 158 - São Geraldo Manaus/Amazonas
A417: Auto Post Ozival XI ( Grupo Oziel Mustafa) | B417: 04643904001168 | C417: Avenida Torquato Tapajós, n.º 5201 A - Flores Manaus/Amazonas
A418: Glayciane Sabino Laranjeira | B418: 68872410215 | C418: - Manaus/Amazonas
A419: Emam Logistica LTDA | B419: 11105987000125 | C419: R.Nelson Rodrigues 01 - Compensa Manaus/Amazonas
A420: 11768 Intelbras S.A Ind. De Telecomunicação Eletrônica Brasileira | B420: 82901000001522 | C420: Av. Tefé, n° 3105 - Japiim Manaus/Amazonas
A421: Hitachi Astemo Manaus Chassis Systens LTDA (Showa) | C421: Rua Quixito, n° 1376 - Distrito Industrial Manaus/Amazonas
A422: Engenheira Carolina
A423: Amazon Aço Indústria e Comércio LTDA | B423: 05477207000175 | C423: Av. Puraquequara, N. 5328 - Puraquequara Manaus/Amazonas
A424: Navegação Cunha LTDA - MAO | B424: 04616801000137 | C424: Rua da Granja Azul N. 02 - Terreo Colônia Oliveira Machado Manaus/Amazonas
...

Sheet TLV _Andrea
A1: Agente Químico | B1: e-Social | D1: Unidade | F1: TWA | G1: STEL | H1: NR 15 | J1: Bases de Efeitos Críticos | K1: Amostrador | L1: CAS | M1: Método de Análise | N1: Metodologia de Amostragem | O1: Vazão | P1: Volume
A2: Acetaldeído | B2: N. C. | C2: Acetaldeído | D2: ppm | E2: Acetaldeído | F2: - | G2: 22 | H2: 78 | I2: Acetaldeído | J2: Irritação no TRS e olhos. | K2: TSG | M2: EPA 8315 | N2: Cromatografia | O2: 0,5 - 1,5 | P2: 30 - 500
A3: Acetamida | B3: N. C. | C3: Acetamida | D3: ppm | E3: Acetamida | F3: 0.88 | G3: - | H3: - | I3: Acetamida | J3: Irritação no TRS e olhos. | K3: -
A4: Acetato de benzila | B4: N. C. | C4: Acetato de benzila | D4: ppm | E4: Acetato de benzila | F4: 8,8 | G4: - | H4: - | I4: Acetato de benzila | J4: Irritação no TRS. | K4: -
A5: Acetato de n-butila | B5: N. C. | C5: Acetato de n-butila | D5: ppm | E5: Acetato de n-butila | F5: 44 | G5: 132 | H5: - | I5: Acetato de n-butila | J5: Irritação nos olhos e no TRS. | K5: TC | M5: NIOSH 1450 | N5: Cromatografia | O5: 0,01 - 0,2 | P5: 1 - 10
A6: Acetato de sec-butila | B6: N. C. | C6: Acetato de sec-butila | D6: ppm | E6: Acetato de sec-butila | F6: 176 | G6: - | H6: - | I6: Acetato de sec-butila | J6: Irritação nos olhos e no TRS. | K6: TC | M6: NIOSH 1450 | N6: Cromatografia | O6: 0,01 - 0,2 | P6: 1 - 10
A7: Acetato de terc-butila | B7: N. C. | C7: Acetato de terc-butila | D7: ppm | E7: Acetato de terc-butila | F7: 176 | G7: - | H7: - | I7: Acetato de terc-butila | J7: Irritação nos olhos e no TRS. | K7: TC | M7: NIOSH 1450 | N7: Cromatografia | O7: 0,01 - 0,2 | P7: 1 - 10
A8: Acetato de 2-butoxietila | B8: N. C. | C8: Acetato de 2-butoxietila | D8: ppm | E8: Acetato de 2-butoxietila | F8: 17,6 | G8: - | H8: - | I8: Acetato de 2-butoxietila | J8: Hemólise | K8: -
A9: Acetato de etila | B9: N. C. | C9: Acetato de etila | D9: ppm | E9: Acetato de etila | F9: 352 | G9: - | H9: 310 | I9: Acetato de etila | J9: Irritação nos olhos e no TRS. | K9: TC | M9: NIOSH 1457 | N9: Cromatografia | O9: 0,01 - 0,2 | P9: <10
A10: Acetato de 2-etoxietila | B10: N. C. | C10: Acetato de 2-etoxietila | D10: ppm | E10: Acetato de 2-etoxietila | F10: 4.4 | G10: - | I10: Acetato de 2-etoxietila | J10: Dano reprodutivo masculino. | K10: TC | M10: NIOSH 1450 | N10: Cromatografia | O10: 0,01 - 0,2 | P10: 1 - 10
A11: Acetato de sec-hexila | B11: N. C. | C11: Acetato de sec-hexila | D11: ppm | E11: Acetato de sec-hexila | F11: 17.6 | G11: - | H11: - | I11: Acetato de sec-hexila | J11: Irritação nos olhos e no TRS. | K11: -
A12: Acetato de isobutila | B12: N. C. | C12: Acetato de isobutila | D12: ppm | E12: Acetato de isobutila | F12: 132 | G12: - | H12: - | I12: Acetato de isobutila | J12: Irritação nos olhos e no TRS. | K12: TC | M12: NIOSH 1450 | N12: Cromatografia | O12: 0,01 - 0,2 | P12: 1 - 10
A13: Acetato de isopropila | B13: N. C. | C13: Acetato de isopropila | D13: ppm | E13: Acetato de isopropila | F13: 88 | G13: 132 | H13: - | I13: Acetato de isopropila | J13: Irritação nos olhos e no TRS; Comprometimento SNC. | K13: TC | M13: NIOSH 1454 | N13: Cromatografia | O13: 0,01 - 0,2 | P13: 0,1 - 9
A14: Acetato de metila | B14: N. C. | C14: Acetato de metila | D14: ppm | E14: Acetato de metila | F14: 176 | G14: 220 | H14: - | I14: Acetato de metila | J14: Dor de cabeça; tontura; náusea; dano olhos (degeneração das células ganglionares da retina). | K14: TC | M14: NIOSH 1458 | N14: Cromatografia | O14: 0,1 - 0,2 | P14: 0,2 - 10
A15: Acetato de 2-metoxietila | B15: N. C. | C15: Acetato de 2-metoxietila | D15: ppm | E15: Acetato de 2-metoxietila | F15: 0.088 | G15: - | H15: - | I15: Acetato de 2-metoxietila | J15: Efeito hematológico; Efeito reprodutivo. | K15: - | M15: - | N15: - | O15: - | P15: -
A16: Acetato de n-propila | B16: N. C. | C16: Acetato de n-propila | D16: ppm | E16: Acetato de n-propila | F16: 176 | G16: 220 | H16: - | I16: Acetato de n-propila | J16: Irritação nos olhos e no TRS. | K16: TC | M16: NIOSH 1450 | N16: Cromatografia | O16: 0,01 - 0,2 | P16: 1 - 10
A17: Acetato de pentila | B17: N. C. | C17: Acetato de pentila | D17: ppm | E17: Acetato de pentila | F17: 44 | G17: 88 | H17: - | I17: Acetato de pentila | J17: Irritação no TRS. | K17: - | M17: - | N17: - | O17: - | P17: -
A18: Acetato de vinila | B18: N. C. | C18: Acetato de vinila | D18: ppm | E18: Acetato de vinila | F18: 8,8 | G18: 13,2 | H18: - | I18: Acetato de vinila | J18: Irritação nos olhos, pele e TRS; Comprometimento do SNC. | K18: TC | M18: NIOSH 1453 | N18: Cromatografia | O18: 0,01 - 0,2 | P18: 1 - 24
A19: Acetileno | B19: N. C. | C19: Acetileno | D19: - | E19: Acetileno | F19: - | G19: - | H19: - | I19: Acetileno | J19: Asfixia | K19: - | M19: - | N19: - | O19: - | P19: -
A20: Acetofenona | B20: N. C. | C20: Acetofenona | D20: ppm | E20: Acetofenona | F20: 8,8 | G20: - | H20: - | I20: Acetofenona | J20: Irritação no TRS, comprometimento do SNC, aborto. | K20: Tenax GC | M20: OSHA PV 2003 | N20: Cromatografia | O20: 0,01 - 0,2 | P20: 1 - 24
A21: Acetona | B21: N. C. | C21: Acetona | D21: ppm | E21: Acetona | F21: 220 | G21: 440 | H21: 780 | I21: Acetona | J21: Irritação no TRS, comprometimento do SNC, efeito hematológico). | K21: TC | M21: NIOSH 1300 | N21: Cromatografia | O21: 0,01 - 0,2 | P21: 0,5 - 3
A22: Acetato cianidrina | B22: N. C. | C22: Acetato cianidrina | D22: mg/m3 | E22: Acetato cianidrina | F22: - | G22: 4,4 | H22: - | I22: Acetato cianidrina | J22: Irritação no TRS; dor de cabeça; hipoxia/cianose. | K22: -
A23: Acetonitrila | B23: N. C. | C23: Acetonitrila | D23: ppm | E23: Acetonitrila | F23: 17,6 | G23: - | H23: 30 | I23: Acetonitrila | J23: Irritação no TRS inferior. | K23: TC | M23: NIOSH 1606 | N23: Cromatografia | O23: 0,01 - 0,2 | P23: 3 - 25
A24: Ácido acético | B24: N. C. | C24: Ácido acético | D24: ppm | E24: Ácido acético | F24: 8,8 | G24: 13,2 | H24: 8 | I24: Ácido acético | J24: Irritação no TRS e olhos, comprometimento pulmonar. | K24: TC | M24: NIOSH 1603 | N24: Cromatografia | O24: 0,01 - 1 | P24: 15 - 300
A25: Ácido acetilsalicílico | B25: N. C. | C25: Ácido acetilsalicílico | D25: mg/m3 | E25: Ácido acetilsalicílico | F25: 4,4 | G25: - | H25: - | I25: Ácido acetilsalicílico | J25: Irritação na pele e olhos. | K25: K7 - | M25: NIOSH 0500 | N25: Gravimetria | O25: 1 - 2 | P25: 1 - 400
A26: Ácido acrílico | B26: N. C. | C26: Ácido acrílico | D26: ppm | E26: Ácido acrílico | F26: 1,76 | G26: - | H26: - | I26: Ácido acrílico | J26: Irritação no TRS. | K26: Tubo Anasorb | M26: OSHA 2005 | N26: Cromatografia | O26: ≤0,1 | P26: 1,5 - 24
A27: Ácido adípico | B27: N. C. | C27: Ácido adípico | D27: mg/m3 | E27: Ácido adípico | F27: 4,4 | G27: - | H27: - | I27: Ácido adípico | J27: Irritação no TRS; comprometimento no SNA. | K27: Tubo de XAD-2 | M27: OSHA SLTC In-House File | N27: Cromatografia | O27: 0.2 | P27: ≤100
A28: Ácido bromídrico | B28: N. C. | C28: Ácido bromídrico | D28: ppm | E28: Ácido bromídrico | F28: - | G28: 1,76 | H28: - | I28: Ácido bromídrico | J28: Irritação no TRS. | K28: K7 | M28: NIOSH 7907 | N28: Cromatografia | O28: 2 | P28: 30
A29: Ácido cianídrico | B29: N. C. | C29: Ácido cianídrico | D29: ppm | E29: Ácido cianídrico | F29: - | G29: 4.15 | H29: 8 | I29: Ácido cianídrico | J29: Irritação TRS; dor de cabeça; náusea; efe tireoide | K29: -
A30: Ácido clorídrico | B30: 02.09.031 | C30: Ácido clorídrico | D30: ppm | E30: Ácido clorídrico | F30: - | G30: 1.76 | H30: 4 | I30: Ácido clorídrico | J30: Irritação TRS | K30: TSG | M30: OSHA ID165-SG / OSHA ID-174-SG | N30: Cromatografia de Íons | O30: 0.5 | P30: 7,5
A31: Ácido 2-cloropropiônico | B31: N. C. | C31: Ácido 2-cloropropiônico | D31: ppm | E31: Ácido 2-cloropropiônico | F31: 0,088 | G31: - | H31: - | I31: Ácido 2-cloropropiônico | J31: Dano reprodutivo masculino | K31: -
A32: Ácido dicloroacético | B32: N. C. | C32: Ácido dicloroacético | D32: ppm | E32: Ácido dicloroacético | F32: 0,44 | G32: - | H32: - | I32: Ácido dicloroacético | J32: Irritação olhos e TRS; dano testicular | K32: -
A33: Ácido 2,2-dicloropropiônico | B33: N. C. | C33: Ácido 2,2-dicloropropiônico | D33: mg/m3 | E33: Ácido 2,2-dicloropropiônico | F33: 4,4 | G33: - | H33: - | I33: Ácido 2,2-dicloropropiônico | J33: Irritação olhos e TRS | K33: -
A34: Ácido 2-etil hexanoico | B34: N. C. | C34: Ácido 2-etil hexanoico | D34: mg/m3 | E34: Ácido 2-etil hexanoico | F34: 4,4 | G34: - | H34: - | I34: Ácido 2-etil hexanoico | J34: Efe teratogênico | K34: -
A35: Ácido fluorídrico | B35: N. C. | C35: Ácido fluorídrico | D35: ppm | E35: Ácido fluorídrico | F35: 0,44 | G35: 1,76 | H35: 2,5 | I35: Ácido fluorídrico | J35: Irritação TRS e TRI; Irritação olhos e pele; fluorose | K35: K7 | M35: NIOSH 7902 | N35: Íons Específicos | O35: 1 - 2 | P35: 1 - 120
A36: Ácido fórmico | B36: N. C. | C36: Ácido fórmico | D36: ppm | E36: Ácido fórmico | F36: 4,4 | G36: 8,8 | H36: 4 | I36: Ácido fórmico | J36: Irritação olhos, pele e TRS | K36: TSG | M36: NIOSH 2011 | N36: Cromatografia | O36: 0,05 - 0,2 | P36: 1 - 24
A37: Ácido fosfórico | B37: 02.12.003 | C37: Ácido fosfórico | D37: mg/m3 | E37: Ácido fosfórico | F37: 0.88 | G37: 2.64 | H37: - | I37: Ácido fosfórico | J37: Irritação olhos, pele e TRS | K37: TSG | M37: OSHA ID165-SG / OSHA ID-174-SG | N37: Cromatografia de Íons | O37: 0,2 L/ min | P37: 96L
A38: Ácido metacrílico | B38: N. C. | C38: Ácido metacrílico | D38: ppm | E38: Ácido metacrílico | F38: 17,6 | G38: - | H38: - | I38: Ácido metacrílico | J38: Irritação olhos e pele
A39: Ácido monocloroacético | B39: N. C. | C39: Ácido monocloroacético | D39: ppm | E39: Ácido monocloroacético | F39: 0,44 | G39: - | H39: - | I39: Ácido monocloroacético | J39: Irritação TRS
A40: Ácido nítrico | B40: N. C. | C40: Ácido nítrico | D40: ppm | E40: Ácido nítrico | F40: 1.76 | G40: 3.52 | H40: - | I40: Ácido nítrico | J40: Irritação olhos e TRS; corrosão dental | K40: TSG | M40: OSHA ID165-SG / OSHA ID-174-SG | N40: Cromatografia de Íons | O40: 0,2 L/ min | P40: 96L
...
